doc_ayush@astro-A320M-S2H:~$ python3 -m venv gbm
doc_ayush@astro-A320M-S2H:~$ source gbm/bin/activate
(gbm) doc_ayush@astro-A320M-S2H:~$ export GEOS_DIR~/.geos_dir
bash: export: `GEOS_DIR~/.geos_dir': not a valid identifier
(gbm) doc_ayush@astro-A320M-S2H:~$ export GEOS_DIR=~/.geos_dir
(gbm) doc_ayush@astro-A320M-S2H:~$ pip3 install /home/doc_ayush/gbm_data_tools-1.1.1.tar.gz
Processing ./gbm_data_tools-1.1.1.tar.gz
ERROR: Exception:
Traceback (most recent call last):
  File "/home/doc_ayush/mambaforge/envs/fermi/lib/python3.9/tarfile.py", line 1691, in gzopen
    t = cls.taropen(name, mode, fileobj, **kwargs)
  File "/home/doc_ayush/mambaforge/envs/fermi/lib/python3.9/tarfile.py", line 1668, in taropen
    return cls(name, mode, fileobj, **kwargs)
  File "/home/doc_ayush/mambaforge/envs/fermi/lib/python3.9/tarfile.py", line 1531, in __init__
    self.firstmember = self.next()
  File "/home/doc_ayush/mambaforge/envs/fermi/lib/python3.9/tarfile.py", line 2363, in next
    raise e
  File "/home/doc_ayush/mambaforge/envs/fermi/lib/python3.9/tarfile.py", line 2336, in next
    tarinfo = self.tarinfo.fromtarfile(self)
  File "/home/doc_ayush/mambaforge/envs/fermi/lib/python3.9/tarfile.py", line 1121, in fromtarfile
    buf = tarfile.fileobj.read(BLOCKSIZE)
  File "/home/doc_ayush/mambaforge/envs/fermi/lib/python3.9/gzip.py", line 300, in read
    return self._buffer.read(size)
  File "/home/doc_ayush/mambaforge/envs/fermi/lib/python3.9/_compression.py", line 68, in readinto
    data = self.read(len(byte_view))
  File "/home/doc_ayush/mambaforge/envs/fermi/lib/python3.9/gzip.py", line 487, in read
    if not self._read_gzip_header():
  File "/home/doc_ayush/mambaforge/envs/fermi/lib/python3.9/gzip.py", line 435, in _read_gzip_header
    raise BadGzipFile('Not a gzipped file (%r)' % magic)
gzip.BadGzipFile: Not a gzipped file (b'pa')

During handling of the above exception, another exception occurred:

Traceback (most recent call last):
  File "/home/doc_ayush/gbm/lib/python3.9/site-packages/pip/_internal/cli/base_command.py", line 167, in exc_logging_wrapper
    status = run_func(*args)
  File "/home/doc_ayush/gbm/lib/python3.9/site-packages/pip/_internal/cli/req_command.py", line 247, in wrapper
    return func(self, options, args)
  File "/home/doc_ayush/gbm/lib/python3.9/site-packages/pip/_internal/commands/install.py", line 369, in run
    requirement_set = resolver.resolve(
  File "/home/doc_ayush/gbm/lib/python3.9/site-packages/pip/_internal/resolution/resolvelib/resolver.py", line 73, in resolve
    collected = self.factory.collect_root_requirements(root_reqs)
  File "/home/doc_ayush/gbm/lib/python3.9/site-packages/pip/_internal/resolution/resolvelib/factory.py", line 491, in collect_root_requirements
    req = self._make_requirement_from_install_req(
  File "/home/doc_ayush/gbm/lib/python3.9/site-packages/pip/_internal/resolution/resolvelib/factory.py", line 453, in _make_requirement_from_install_req
    cand = self._make_candidate_from_link(
  File "/home/doc_ayush/gbm/lib/python3.9/site-packages/pip/_internal/resolution/resolvelib/factory.py", line 206, in _make_candidate_from_link
    self._link_candidate_cache[link] = LinkCandidate(
  File "/home/doc_ayush/gbm/lib/python3.9/site-packages/pip/_internal/resolution/resolvelib/candidates.py", line 297, in __init__
    super().__init__(
  File "/home/doc_ayush/gbm/lib/python3.9/site-packages/pip/_internal/resolution/resolvelib/candidates.py", line 162, in __init__
    self.dist = self._prepare()
  File "/home/doc_ayush/gbm/lib/python3.9/site-packages/pip/_internal/resolution/resolvelib/candidates.py", line 231, in _prepare
    dist = self._prepare_distribution()
  File "/home/doc_ayush/gbm/lib/python3.9/site-packages/pip/_internal/resolution/resolvelib/candidates.py", line 308, in _prepare_distribution
    return preparer.prepare_linked_requirement(self._ireq, parallel_builds=True)
  File "/home/doc_ayush/gbm/lib/python3.9/site-packages/pip/_internal/operations/prepare.py", line 438, in prepare_linked_requirement
    return self._prepare_linked_requirement(req, parallel_builds)
  File "/home/doc_ayush/gbm/lib/python3.9/site-packages/pip/_internal/operations/prepare.py", line 483, in _prepare_linked_requirement
    local_file = unpack_url(
  File "/home/doc_ayush/gbm/lib/python3.9/site-packages/pip/_internal/operations/prepare.py", line 175, in unpack_url
    unpack_file(file.path, location, file.content_type)
  File "/home/doc_ayush/gbm/lib/python3.9/site-packages/pip/_internal/utils/unpacking.py", line 246, in unpack_file
    untar_file(filename, location)
  File "/home/doc_ayush/gbm/lib/python3.9/site-packages/pip/_internal/utils/unpacking.py", line 173, in untar_file
    tar = tarfile.open(filename, mode, encoding="utf-8")
  File "/home/doc_ayush/mambaforge/envs/fermi/lib/python3.9/tarfile.py", line 1638, in open
    return func(name, filemode, fileobj, **kwargs)
  File "/home/doc_ayush/mambaforge/envs/fermi/lib/python3.9/tarfile.py", line 1695, in gzopen
    raise ReadError("not a gzip file")
tarfile.ReadError: not a gzip file
(gbm) doc_ayush@astro-A320M-S2H:~$ pip3 install /home/doc_ayush/gbm_data_tools-1.1.1.tar.gz[basemap]
Processing ./gbm_data_tools-1.1.1.tar.gz
ERROR: Exception:
Traceback (most recent call last):
  File "/home/doc_ayush/mambaforge/envs/fermi/lib/python3.9/tarfile.py", line 1691, in gzopen
    t = cls.taropen(name, mode, fileobj, **kwargs)
  File "/home/doc_ayush/mambaforge/envs/fermi/lib/python3.9/tarfile.py", line 1668, in taropen
    return cls(name, mode, fileobj, **kwargs)
  File "/home/doc_ayush/mambaforge/envs/fermi/lib/python3.9/tarfile.py", line 1531, in __init__
    self.firstmember = self.next()
  File "/home/doc_ayush/mambaforge/envs/fermi/lib/python3.9/tarfile.py", line 2363, in next
    raise e
  File "/home/doc_ayush/mambaforge/envs/fermi/lib/python3.9/tarfile.py", line 2336, in next
    tarinfo = self.tarinfo.fromtarfile(self)
  File "/home/doc_ayush/mambaforge/envs/fermi/lib/python3.9/tarfile.py", line 1121, in fromtarfile
    buf = tarfile.fileobj.read(BLOCKSIZE)
  File "/home/doc_ayush/mambaforge/envs/fermi/lib/python3.9/gzip.py", line 300, in read
    return self._buffer.read(size)
  File "/home/doc_ayush/mambaforge/envs/fermi/lib/python3.9/_compression.py", line 68, in readinto
    data = self.read(len(byte_view))
  File "/home/doc_ayush/mambaforge/envs/fermi/lib/python3.9/gzip.py", line 487, in read
    if not self._read_gzip_header():
  File "/home/doc_ayush/mambaforge/envs/fermi/lib/python3.9/gzip.py", line 435, in _read_gzip_header
    raise BadGzipFile('Not a gzipped file (%r)' % magic)
gzip.BadGzipFile: Not a gzipped file (b'pa')

During handling of the above exception, another exception occurred:

Traceback (most recent call last):
  File "/home/doc_ayush/gbm/lib/python3.9/site-packages/pip/_internal/cli/base_command.py", line 167, in exc_logging_wrapper
    status = run_func(*args)
  File "/home/doc_ayush/gbm/lib/python3.9/site-packages/pip/_internal/cli/req_command.py", line 247, in wrapper
    return func(self, options, args)
  File "/home/doc_ayush/gbm/lib/python3.9/site-packages/pip/_internal/commands/install.py", line 369, in run
    requirement_set = resolver.resolve(
  File "/home/doc_ayush/gbm/lib/python3.9/site-packages/pip/_internal/resolution/resolvelib/resolver.py", line 73, in resolve
    collected = self.factory.collect_root_requirements(root_reqs)
  File "/home/doc_ayush/gbm/lib/python3.9/site-packages/pip/_internal/resolution/resolvelib/factory.py", line 491, in collect_root_requirements
    req = self._make_requirement_from_install_req(
  File "/home/doc_ayush/gbm/lib/python3.9/site-packages/pip/_internal/resolution/resolvelib/factory.py", line 453, in _make_requirement_from_install_req
    cand = self._make_candidate_from_link(
  File "/home/doc_ayush/gbm/lib/python3.9/site-packages/pip/_internal/resolution/resolvelib/factory.py", line 206, in _make_candidate_from_link
    self._link_candidate_cache[link] = LinkCandidate(
  File "/home/doc_ayush/gbm/lib/python3.9/site-packages/pip/_internal/resolution/resolvelib/candidates.py", line 297, in __init__
    super().__init__(
  File "/home/doc_ayush/gbm/lib/python3.9/site-packages/pip/_internal/resolution/resolvelib/candidates.py", line 162, in __init__
    self.dist = self._prepare()
  File "/home/doc_ayush/gbm/lib/python3.9/site-packages/pip/_internal/resolution/resolvelib/candidates.py", line 231, in _prepare
    dist = self._prepare_distribution()
  File "/home/doc_ayush/gbm/lib/python3.9/site-packages/pip/_internal/resolution/resolvelib/candidates.py", line 308, in _prepare_distribution
    return preparer.prepare_linked_requirement(self._ireq, parallel_builds=True)
  File "/home/doc_ayush/gbm/lib/python3.9/site-packages/pip/_internal/operations/prepare.py", line 438, in prepare_linked_requirement
    return self._prepare_linked_requirement(req, parallel_builds)
  File "/home/doc_ayush/gbm/lib/python3.9/site-packages/pip/_internal/operations/prepare.py", line 483, in _prepare_linked_requirement
    local_file = unpack_url(
  File "/home/doc_ayush/gbm/lib/python3.9/site-packages/pip/_internal/operations/prepare.py", line 175, in unpack_url
    unpack_file(file.path, location, file.content_type)
  File "/home/doc_ayush/gbm/lib/python3.9/site-packages/pip/_internal/utils/unpacking.py", line 246, in unpack_file
    untar_file(filename, location)
  File "/home/doc_ayush/gbm/lib/python3.9/site-packages/pip/_internal/utils/unpacking.py", line 173, in untar_file
    tar = tarfile.open(filename, mode, encoding="utf-8")
  File "/home/doc_ayush/mambaforge/envs/fermi/lib/python3.9/tarfile.py", line 1638, in open
    return func(name, filemode, fileobj, **kwargs)
  File "/home/doc_ayush/mambaforge/envs/fermi/lib/python3.9/tarfile.py", line 1695, in gzopen
    raise ReadError("not a gzip file")
tarfile.ReadError: not a gzip file
(gbm) doc_ayush@astro-A320M-S2H:~$ 

